Workbook

Sheet Cover
C2: Valuation Analysis Report
C4: DCF Anlysis | Comparable Companies | Precendent Transactions | U4: Confidential | For Internal Use Only
C6: Targeted Company: RH
C7: Prepared By: Frey Guo
C8: Date: May 2026
C9: Version: 1.0
C13: Table of Contents | O13: Model Checks
C15: Dashboard | O15: Incorrect Date Set for Valuation? | U15: =IF('DCF Inputs'!M50>'DCF Inputs'!M51,"yes", "No") -> No
C16: Sensitivity Analysis | O16: Incorrect Date Set for First Cash Flow? | U16: =IF('DCF Inputs'!M51>'DCF Inputs'!M52,"Yes","No") -> No
C17: Input | O17: Terminal Growth Rate Greater Than or Equal To WACC? | U17: =IF('DCF Inputs'!G54<='DCF Inputs'!G52,"Yes","No") -> No
C18: DCF Model | O18: Unused Tax Losses Remaining? (Levered Schedule) | U18: =IF('DCF Model'!P161=0,"No","Yes") -> No
C19: Comparable Anlysis | O19: Unused Tax Losses Remaining? (Unlevered Schedule) | U19: =IF('DCF Model'!P194=0,"No","Yes") -> No
C20: Precendent Transactions | O20: Two UFCF Methods Different? | U20: =IF(SUM('DCF Model'!L215:Q215)=SUM('DCF Model'!L225:Q225),"No","Yes") -> No
C21: RH Fiancial Report
C28: Disclamer
C29: This valuation analysis has been prepared solely for career, academic, and internal discussion purposes. The information contained herein is based on publicly available data and assumptions believed to be reasonable at the time of preparation. This report does not constitute investment advice, a recommendation, or an offer to buy or sell any security. Actual results may differ materially from the estimates and projections presented.

Sheet Dashboard
B2: Projected Business Performance | O2: Data: Company Overview
O4: Company Information
B5: =CONCATENATE("Company Name: "&Q5) -> Company Name: RH | E5: =CONCATENATE("Recommendation: "&Q6) -> Recommendation: Hold | L5: =CONCATENATE("Target Price: "&Q7) -> Target Price: 173.21 | O5: Company Name | Q5: RH
O6: Recommendation | Q6: Hold
O7: Target Price | Q7: 173.21
C17: Valuation Summary: Football Field Chart
C43: Valuation Graphing Data
D45: Low | E45: Delta | F45: High | G45: Mid
C46: DCF Valuation Analysis | D46: ='DCF Sensitivity Analysis'!H14 -> 49.917683 | E46: =F46-D46 -> 238.00976 | F46: ='DCF Sensitivity Analysis'!H12 -> 287.92744 | G46: =D46+E46/2 -> 168.92256
C47: Comparable Trading Analysis | D47: =Comps!J29 -> 9.9286213 | E47: =F47-D47 -> 220.43367 | F47: =Comps!J28 -> 230.36229 | G47: =D47+E47/2 -> 120.14546
C48: Precedent Transaction Analysis | D48: =Transactions!M29 -> -2.6847844 | E48: =F48-D48 -> 294.58406 | F48: =Transactions!M28 -> 291.89927 | G48: =D48+E48/2 -> 144.60724
C49: 52-Week Trading | D49: 106.3 | E49: =F49-D49 -> 150.7 | F49: 257 | G49: =D49+E49/2 -> 181.65
C50: Consensus Research | D50: 88 | E50: =F50-D50 -> 187 | F50: 275 | G50: =D50+E50/2 -> 181.5

Sheet DCF Sensitivity Analysis
B3: Dashboard: Perpetuity Method
C5: Model Drivers Set To | D5: 2 | L5: All figures in USD MM unless stated
D7: Main Outputs 1 | L7: Selected Inputs
F9: Enterprise | G9: Equity | H9: Equity | L9: Terminal Growth Rate | O9: ='DCF Model'!C232 -> 0.025
F10: Value | G10: Value | H10: Per Share | L10: WACC | O10: ='DCF Model'!C233 -> 0.083031313
F11: ='DCF Model'!K258 -> 6900.4788 | L11: Net Debt | N11: (End of 2025) | O11: ='DCF Inputs'!M41 -> 3930
D12: Best Case | E12: 1 | F12: 9112.694 | G12: =F12-$O$11 -> 5182.694 | H12: =G12/$O$12 -> 287.92744 | L12: Shares Outstanding | N12: (mm) | O12: ='DCF Inputs'!G50 -> 18
D13: Base Case | E13: =E12+1 -> 2 | F13: 6900.4788 | G13: =F13-$O$11 -> 2970.4788 | H13: =G13/$O$12 -> 165.0266 | L13: Current Stock Price | N13: (US$/sh) | O13: ='DCF Inputs'!G51 -> 136.42
D14: Worst Case | E14: =E13+1 -> 3 | F14: 4828.5183 | G14: =F14-$O$11 -> 898.51829 | H14: =G14/$O$12 -> 49.917683
D16: Enterprise Value 1 | L16: Equity Value per Share
D18: Terminal Growth Rate | L18: Terminal Growth Rate
C19: ='DCF Model'!K259 -> 6898.2991 | D19: =E19-0.0025 -> 0.02 | E19: =F19-0.0025 -> 0.0225 | F19: =O9 -> 0.025 | G19: =F19+0.0025 -> 0.0275 | H19: =G19+0.0025 -> 0.03 | L19: =D19 -> 0.02 | M19: =E19 -> 0.0225 | N19: =F19 -> 0.025 | O19: =G19 -> 0.0275 | P19: =H19 -> 0.03
B20: WACC | C20: =C21-0.005 -> 0.073031313 | D20: ='DCF Model'!D315 -> 7754.815 | E20: ='DCF Model'!E315 -> 8097.8078 | F20: ='DCF Model'!F315 -> 8476.5056 | G20: ='DCF Model'!G315 -> 8896.7901 | H20: ='DCF Model'!H315 -> 9365.9092 | J20: WACC | K20: =C20 -> 0.073031313 | L20: =D31/$O$12 -> 212.48972 | M20: =E31/$O$12 -> 231.54488 | N20: =F31/$O$12 -> 252.58365 | O20: =G31/$O$12 -> 275.93278 | P20: =H31/$O$12 -> 301.99495
C21: =C22-0.005 -> 0.078031313 | D21: ='DCF Model'!D316 -> 7027.4825 | E21: ='DCF Model'!E316 -> 7307.3088 | F21: ='DCF Model'!F316 -> 7613.5182 | G21: ='DCF Model'!G316 -> 7950.0266 | H21: ='DCF Model'!H316 -> 8321.5651 | K21: =C21 -> 0.078031313 | L21: =D32/$O$12 -> 172.08236 | M21: =E32/$O$12 -> 187.62827 | N21: =F32/$O$12 -> 204.6399 | O21: =G32/$O$12 -> 223.33481 | P21: =H32/$O$12 -> 243.97584
C22: =O10 -> 0.083031313 | D22: ='DCF Model'!D317 -> 6416.6971 | E22: ='DCF Model'!E317 -> 6648.5977 | F22: ='DCF Model'!F317 -> 6900.4788 | G22: ='DCF Model'!G317 -> 7175.0392 | H22: ='DCF Model'!H317 -> 7475.4862 | K22: =C22 -> 0.083031313 | L22: =D33/$O$12 -> 138.14984 | M22: =E33/$O$12 -> 151.0332 | N22: =F33/$O$12 -> 165.0266 | O22: =G33/$O$12 -> 180.27996 | P22: =H33/$O$12 -> 196.97146
C23: =C22+0.005 -> 0.088031313 | D23: ='DCF Model'!D318 -> 5896.7339 | E23: ='DCF Model'!E318 -> 6091.4796 | F23: ='DCF Model'!F318 -> 6301.6736 | G23: ='DCF Model'!G318 -> 6529.23 | H23: ='DCF Model'!H318 -> 6776.3927 | K23: =C23 -> 0.088031313 | L23: =D34/$O$12 -> 109.263 | M23: =E34/$O$12 -> 120.0822 | N23: =F34/$O$12 -> 131.75964 | O23: =G34/$O$12 -> 144.40167 | P23: =H34/$O$12 -> 158.13293
C24: =C23+0.005 -> 0.093031313 | D24: ='DCF Model'!D319 -> 5448.9135 | E24: ='DCF Model'!E319 -> 5614.3227 | F24: ='DCF Model'!F319 -> 5791.8886 | G24: ='DCF Model'!G319 -> 5983.0027 | H24: ='DCF Model'!H319 -> 6189.2771 | K24: =C24 -> 0.093031313 | L24: =D35/$O$12 -> 84.384086 | M24: =E35/$O$12 -> 93.573481 | N24: =F35/$O$12 -> 103.43826 | O24: =G35/$O$12 -> 114.05571 | P24: =H35/$O$12 -> 125.51539
D27: Equity Value | L27: Premium (Discount) to Stock Price
D29: Terminal Growth Rate | L29: Terminal Growth Rate
D30: =D19 -> 0.02 | E30: =E19 -> 0.0225 | F30: =F19 -> 0.025 | G30: =G19 -> 0.0275 | H30: =H19 -> 0.03 | L30: =D30 -> 0.02 | M30: =E30 -> 0.0225 | N30: =F30 -> 0.025 | O30: =G30 -> 0.0275 | P30: =H30 -> 0.03
B31: WACC | C31: =C20 -> 0.073031313 | D31: =D20-$O$11 -> 3824.815 | E31: =E20-$O$11 -> 4167.8078 | F31: =F20-$O$11 -> 4546.5056 | G31: =G20-$O$11 -> 4966.7901 | H31: =H20-$O$11 -> 5435.9092 | J31: WACC | K31: =C31 -> 0.073031313 | L31: =L20/$O$13-1 -> 0.55761415 | M31: =M20/$O$13-1 -> 0.69729421 | N31: =N20/$O$13-1 -> 0.85151479 | O31: =O20/$O$13-1 -> 1.022671 | P31: =P20/$O$13-1 -> 1.2137147
C32: =C21 -> 0.078031313 | D32: =D21-$O$11 -> 3097.4825 | E32: =E21-$O$11 -> 3377.3088 | F32: =F21-$O$11 -> 3683.5182 | G32: =G21-$O$11 -> 4020.0266 | H32: =H21-$O$11 -> 4391.5651 | K32: =C32 -> 0.078031313 | L32: =L21/$O$13-1 -> 0.26141592 | M32: =M21/$O$13-1 -> 0.37537213 | N32: =N21/$O$13-1 -> 0.50007258 | O32: =O21/$O$13-1 -> 0.63711195 | P32: =P21/$O$13-1 -> 0.78841695
C33: =C22 -> 0.083031313 | D33: =D22-$O$11 -> 2486.6971 | E33: =E22-$O$11 -> 2718.5977 | F33: =F22-$O$11 -> 2970.4788 | G33: =G22-$O$11 -> 3245.0392 | H33: =H22-$O$11 -> 3545.4862 | K33: =C33 -> 0.083031313 | L33: =L22/$O$13-1 -> 0.012680257 | M33: =M22/$O$13-1 -> 0.10711922 | N33: =N22/$O$13-1 -> 0.20969508 | O33: =O22/$O$13-1 -> 0.32150679 | P33: =P22/$O$13-1 -> 0.44386055
C34: =C23 -> 0.088031313 | D34: =D23-$O$11 -> 1966.7339 | E34: =E23-$O$11 -> 2161.4796 | F34: =F23-$O$11 -> 2371.6736 | G34: =G23-$O$11 -> 2599.23 | H34: =H23-$O$11 -> 2846.3927 | K34: =C34 -> 0.088031313 | L34: =L23/$O$13-1 -> -0.19906908 | M34: =M23/$O$13-1 -> -0.11976104 | N34: =N23/$O$13-1 -> -0.034161828 | O34: =O23/$O$13-1 -> 0.058508035 | P34: =P23/$O$13-1 -> 0.15916237
C35: =C24 -> 0.093031313 | D35: =D24-$O$11 -> 1518.9135 | E35: =E24-$O$11 -> 1684.3227 | F35: =F24-$O$11 -> 1861.8886 | G35: =G24-$O$11 -> 2053.0027 | H35: =H24-$O$11 -> 2259.2771 | K35: =C35 -> 0.093031313 | L35: =L24/$O$13-1 -> -0.38143904 | M35: =M24/$O$13-1 -> -0.31407799 | N35: =N24/$O$13-1 -> -0.24176619 | O35: =O24/$O$13-1 -> -0.16393705 | P35: =P24/$O$13-1 -> -0.079934068
P37: These tables require the workbook calculation to be set to automatic to update.
B40: Dashboard: Multiple Method
C42: Model Drivers Set To | D42: =D5 -> 2 | L42: All figures in USD MM unless stated
D44: Main Outputs 2 | L44: Main Outputs 1
F46: Enterprise | G46: Equity | H46: Equity | L46: Terminal Multiple | O46: ='DCF Inputs'!G53 -> 9
F47: Value | G47: Value | H47: Per Share | L47: WACC | O47: =O10 -> 0.083031313
F48: ='DCF Model'!K300 -> 6189.4224 | L48: Net Debt | N48: =N11 -> (End of 2025) | O48: =O11 -> 3930
D49: Best Case | E49: 1 | F49: 7724.9797 | G49: =F49-$O$48 -> 3794.9797 | H49: =G49/$O$49 -> 210.83221 | L49: Shares Outstanding | N49: (mm) | O49: =O12 -> 18
D50: Base Case | E50: 2 | F50: 6189.4224 | G50: =F50-$O$48 -> 2259.4224 | H50: =G50/$O$49 -> 125.52347 | L50: Current Stock Price | N50: (US$/sh) | O50: =O13 -> 136.42
D51: Worst Case | E51: 3 | F51: 4743.8182 | G51: =F51-$O$48 -> 813.81816 | H51: =G51/$O$49 -> 45.21212
D53: Enterprise Value 2 | L53: Equity Value per Share
D55: Terminal Multiple | L55: Terminal Multiple
C56: ='DCF Model'!K301 -> 6187.4714 | D56: =E56-0.5 -> 8 | E56: =F56-0.5 -> 8.5 | F56: =O46 -> 9 | G56: =+F56+0.5 -> 9.5 | H56: =+G56+0.5 -> 10 | L56: =D56 -> 8 | M56: =E56 -> 8.5 | N56: =F56 -> 9 | O56: =G56 -> 9.5 | P56: =H56 -> 10
B57: WACC | C57: =C20 -> 0.073031313 | D57: ='DCF Model'!L315 -> 5903.326 | E57: ='DCF Model'!M315 -> 6199.4904 | F57: ='DCF Model'!N315 -> 6495.6548 | G57: ='DCF Model'!O315 -> 6791.8192 | H57: ='DCF Model'!P315 -> 7087.9836 | J57: WACC | K57: =C57 -> 0.073031313 | L57: =D68/$O$49 -> 109.62922 | M57: =E68/$O$49 -> 126.0828 | N57: =F68/$O$49 -> 142.53638 | O57: =G68/$O$49 -> 158.98996 | P57: =H68/$O$49 -> 175.44353
C58: =C21 -> 0.078031313 | D58: ='DCF Model'!L316 -> 5763.1664 | E58: ='DCF Model'!M316 -> 6051.7126 | F58: ='DCF Model'!N316 -> 6340.2588 | G58: ='DCF Model'!O316 -> 6628.805 | H58: ='DCF Model'!P316 -> 6917.3512 | K58: =C58 -> 0.078031313 | L58: =D69/$O$49 -> 101.84258 | M58: =E69/$O$49 -> 117.87292 | N58: =F69/$O$49 -> 133.90327 | O58: =G69/$O$49 -> 149.93361 | P58: =H69/$O$49 -> 165.96396
...

Sheet DCF Inputs
C2: Drivers
C4: Driver Switcher | D4: ='DCF Sensitivity Analysis'!$D$5 -> 2
G5: 2026 | H5: =G5+1 -> 2027 | I5: =H5+1 -> 2028 | J5: =I5+1 -> 2029 | K5: =J5+1 -> 2030 | L5: Terms
C7: Revenue Growth | G7: =CHOOSE($D$4,G9,G10,G11) -> 0.05 | H7: =CHOOSE($D$4,H9,H10,H11) -> 0.04 | I7: =CHOOSE($D$4,I9,I10,I11) -> 0.035 | J7: =CHOOSE($D$4,J9,J10,J11) -> 0.035 | K7: =CHOOSE($D$4,K9,K10,K11) -> 0.05 | L7: =CHOOSE($D$4,L9,L10,L11) -> 0.05
C9: Best Case | G9: 0.06 | H9: 0.05 | I9: 0.045 | J9: 0.045 | K9: 0.06 | L9: 0.06
C10: Base Case | G10: 0.05 | H10: 0.04 | I10: 0.035 | J10: 0.035 | K10: 0.05 | L10: 0.05
C11: Worst Case | G11: 0.04 | H11: 0.03 | I11: 0.025 | J11: 0.025 | K11: 0.04 | L11: 0.04
C14: COGS % of Revenue | G14: =CHOOSE($D$4,G16,G17,G18) -> 0.555 | H14: =CHOOSE($D$4,H16,H17,H18) -> 0.553 | I14: =CHOOSE($D$4,I16,I17,I18) -> 0.55 | J14: =CHOOSE($D$4,J16,J17,J18) -> 0.548 | K14: =CHOOSE($D$4,K16,K17,K18) -> 0.545 | L14: =CHOOSE($D$4,L16,L17,L18) -> 0.5225
C16: Best Case | G16: 0.54 | H16: 0.538 | I16: 0.535 | J16: 0.533 | K16: 0.53 | L16: 0.5075
C17: Base Case | G17: 0.555 | H17: 0.553 | I17: 0.55 | J17: 0.548 | K17: 0.545 | L17: 0.5225
C18: Worst Case | G18: 0.57 | H18: 0.568 | I18: 0.565 | J18: 0.563 | K18: 0.56 | L18: 0.5375
C20: CapEx % of Revenue | G20: =CHOOSE($D$4,G22,G23,G24) -> 0.06 | H20: =CHOOSE($D$4,H22,H23,H24) -> 0.058 | I20: =CHOOSE($D$4,I22,I23,I24) -> 0.055 | J20: =CHOOSE($D$4,J22,J23,J24) -> 0.053 | K20: =CHOOSE($D$4,K22,K23,K24) -> 0.05 | L20: =CHOOSE($D$4,L22,L23,L24) -> 0.047
C22: Best Case | G22: 0.055 | H22: 0.053 | I22: 0.05 | J22: 0.048 | K22: 0.045 | L22: 0.042
C23: Base Case | G23: 0.06 | H23: 0.058 | I23: 0.055 | J23: 0.053 | K23: 0.05 | L23: 0.047
C24: Worst Case | G24: 0.065 | H24: 0.063 | I24: 0.06 | J24: 0.058 | K24: 0.055 | L24: 0.052
C26: Inflation | G26: 0.027 | H26: 0.025 | I26: 0.02 | J26: 0.02 | K26: 0.02 | L26: 0.015
C28: Working Capital
C29: Accounts Receivable | D29: (Days) | G29: 10 | H29: 10 | I29: 10 | J29: 10 | K29: 10 | L29: 10
C30: Inventory | D30: (Days) | G30: 150 | H30: 150 | I30: 150 | J30: 150 | K30: 150 | L30: 150
C31: Accounts Payable | D31: (Days) | G31: 45 | H31: 45 | I31: 45 | J31: 45 | K31: 45 | L31: 45
C32: prepaids % SG&A | G32: 0.025 | H32: 0.025 | I32: 0.025 | J32: 0.025 | K32: 0.025 | L32: 0.025
C33: other operating Assets & Revenue | G33: 0.012 | H33: 0.012 | I33: 0.012 | J33: 0.012 | K33: 0.012 | L33: 0.012
C34: Accrued Payroll % SG&A | G34: 0.02 | H34: 0.02 | I34: 0.02 | J34: 0.02 | K34: 0.02 | L34: 0.02
C35: Deferred Revenue (Current) % Revenue | G35: 0.1 | H35: 0.1 | I35: 0.1 | J35: 0.1 | K35: 0.1 | L35: 0.1
C36: Other Current Liabilities & Revenue | G36: 0.05 | H36: 0.05 | I36: 0.05 | J36: 0.05 | K36: 0.05 | L36: 0.05
C38: Other inputs
C40: Other inputs | I40: End of 2025 Balances
C41: Projected Interest Expense | G41: 200 | I41: Net Debt | M41: ='RH Financial Report'!H41 -> 3930
C42: First Year Tax Depreciation | G42: 0.5 | I42: Property Plant & Equipment | M42: ='RH Financial Report'!H27 -> 3110
C43: Blended Tax Depreciation Rate | G43: 0.1 | I43: Tax Basis for PP&E | M43: 704.956
C44: First Year Accounting Depreciation | G44: 0.4 | I44: Tax Losses | M44: 35.02
C45: Useful Life: Existing Assets | F45: (Years) | G45: 16
C46: Useful Life: New Assets | F46: (Years) | G46: 20
C47: Tax Rate | G47: 0.24
C49: Valuation | I49: Dates
C50: Shares Outstanding | F50: (mm) | G50: 18 | I50: Valuation Date | L50: (YY-MM-DD) | M50: 46164
C51: Current Stock Price | F51: (US$/sh) | G51: 136.42 | I51: First Expected Cash Flow | L51: (YY-MM-DD) | M51: 46203
C52: Terminal Growth Rate | G52: 0.025 | I52: First Fiscal Year End for Forecast | L52: (YY-MM-DD) | M52: 46387
C53: Terminal EBITDA Multiple 1 | G53: 9 | I53: First Year of Forecast | L53: (YYYY) | M53: =YEAR(M52) -> 2026
C54: Weighted Average Cost of Capital (WACC) | G54: =M96 -> 0.083031313 | I54: Incorrect Date Set for Valuation? | M54: =IF(M50>M51,1,0) -> 0
...

Sheet DCF Model
B2: Revenue/COGOS Schedules
B4: All figures in USD mm unless stated | F4: 2020 | G4: =F4+1 -> 2021 | H4: =G4+1 -> 2022 | I4: =H4+1 -> 2023 | J4: =I4+1 -> 2024 | K4: =J4+1 -> 2025 | L4: =K4+1 -> 2026 | M4: =L4+1 -> 2027 | N4: =M4+1 -> 2028 | ... P4: =O4+1 -> 2030 | Q4: Terms
B6: Revenue Growth | G6: 0.31929825 | H6: -0.045212766 | I6: -0.15598886 | J6: 0.04950495 | K6: 0.081761006 | L6: ='DCF Inputs'!G7 -> 0.05 | M6: ='DCF Inputs'!H7 -> 0.04 | N6: ='DCF Inputs'!I7 -> 0.035 | O6: ='DCF Inputs'!J7 -> 0.035 | P6: ='DCF Inputs'!K7 -> 0.05 | Q6: ='DCF Inputs'!L7 -> 0.05
B7: Revenue | F7: 2850 | G7: 3760 | H7: 3590 | I7: 3030 | J7: 3180 | K7: 3440 | L7: =K7*(1+L6) -> 3612 | M7: =L7*(1+M6) -> 3756.48 | N7: =M7*(1+N6) -> 3887.9568 | O7: =N7*(1+O6) -> 4024.0353 | P7: =O7*(1+P6) -> 4225.2371 | Q7: =P7*(1+Q6) -> 4436.4989
B9: COGS % of Revenue | F9: -0.53333333 | G9: -0.50531915 | H9: -0.49582173 | I9: -0.54125413 | J9: -0.55660377 | K9: -0.55813953 | L9: ='DCF Inputs'!G14 -> 0.555 | M9: ='DCF Inputs'!H14 -> 0.553 | N9: ='DCF Inputs'!I14 -> 0.55 | O9: ='DCF Inputs'!J14 -> 0.548 | P9: ='DCF Inputs'!K14 -> 0.545 | Q9: ='DCF Inputs'!L14 -> 0.5225
B10: COGS | F10: 1520 | G10: 1900 | H10: 1780 | I10: 1640 | J10: 1770 | K10: 1920 | L10: =L7*L9 -> 2004.66 | M10: =M7*M9 -> 2077.3334 | N10: =N7*N9 -> 2138.3762 | O10: =O7*O9 -> 2205.1713 | P10: =P7*P9 -> 2302.7542 | Q10: =Q7*Q9 -> 2318.0707
B12: Income Statements
B14: All figures in USD mm unless stated | F14: 2020 | G14: =F14+1 -> 2021 | H14: =G14+1 -> 2022 | I14: =H14+1 -> 2023 | J14: =I14+1 -> 2024 | K14: =J14+1 -> 2025 | L14: =K14+1 -> 2026 | M14: =L14+1 -> 2027 | N14: =M14+1 -> 2028 | ... P14: =O14+1 -> 2030 | Q14: Terms
B16: Inflation | F16: 0.03 | G16: 0.03 | H16: 0.03 | I16: 0.03 | J16: 0.03 | K16: 0.03 | L16: ='DCF Inputs'!G26 -> 0.027 | M16: ='DCF Inputs'!H26 -> 0.025 | N16: ='DCF Inputs'!I26 -> 0.02 | O16: ='DCF Inputs'!J26 -> 0.02 | P16: ='DCF Inputs'!K26 -> 0.02 | Q16: ='DCF Inputs'!L26 -> 0.015
B18: Interest Expense | C18: ='DCF Inputs'!G41 -> 200
B19: Tax Rate | C19: ='DCF Inputs'!G47 -> 0.24
B21: Revenue | F21: 2850 | G21: 3760 | H21: 3590 | I21: 3030 | J21: 3180 | K21: 3440 | L21: =L7 -> 3612 | M21: =M7 -> 3756.48 | N21: =N7 -> 3887.9568 | O21: =O7 -> 4024.0353 | P21: =P7 -> 4225.2371 | Q21: =Q7 -> 4436.4989
B22: COGS | F22: -1355.83 | G22: -1731.5 | H22: -1596.23 | I22: -1521.01 | J22: -1639.81 | K22: -1771.5 | L22: =L10*-1-L29 -> -1805.9506 | M22: =M10*-1-M29 -> -1867.788 | N22: =N10*-1-N29 -> -1917.9948 | O22: =O10*-1-O29 -> -1973.9539 | P22: =P10*-1-P29 -> -2060.7008 | Q22: =Q10*-1-Q29 -> -2109.5552
B23: Gross Profit | F23: 1330 | G23: 1860 | H23: 1810 | I23: 1390 | J23: 1410 | K23: 1520 | L23: =SUM(L21:L22) -> 1806.0494 | M23: =SUM(M21:M22) -> 1888.692 | N23: =SUM(N21:N22) -> 1969.962 | O23: =SUM(O21:O22) -> 2050.0814 | P23: =SUM(P21:P22) -> 2164.5363 | Q23: =SUM(Q21:Q22) -> 2326.9437
B25: SG&A | F25: -839.52 | G25: -922 | H25: -1070 | I25: -1030 | J25: -1050 | K25: -1130 | L25: =K25*(1+L16) -> -1160.51 | M25: =L25*(1+M16) -> -1189.5227 | N25: =M25*(1+N16) -> -1213.3132 | O25: =N25*(1+O16) -> -1237.5795 | P25: =O25*(1+P16) -> -1262.3311 | Q25: =P25*(1+Q16) -> -1281.266
B26: Other | F26: =F23-F27+F25 -> -162.11 | G26: =G23-G27+G25 -> -163 | H26: =H23-H27+H25 -> -189.85 | I26: =I23-I27+I25 -> -122.17 | J26: =J23-J27+J25 -> -137.95 | K26: =K23-K27+K25 -> -146.69 | L26: =K26*(1+L16) -> -150.65063 | M26: =L26*(1+M16) -> -154.4169 | N26: =M26*(1+N16) -> -157.50523 | O26: =N26*(1+O16) -> -160.65534 | P26: =O26*(1+P16) -> -163.86845 | Q26: =P26*(1+Q16) -> -166.32647
B27: EBITDA | F27: 652.59 | G27: 1101 | H27: 929.85 | I27: 482.17 | J27: 497.95 | K27: 536.69 | L27: =L23+L25+L26 -> 494.88877 | M27: =M23+M25+M26 -> 544.75231 | N27: =N23+N25+N26 -> 599.14352 | O27: =O23+O25+O26 -> 651.84654 | P27: =P23+P25+P26 -> 738.33676 | Q27: =Q23+Q25+Q26 -> 879.35118
B29: Depreciation | F29: -164.17 | G29: -168.5 | H29: -183.77 | I29: -118.99 | J29: -130.19 | K29: -148.5 | L29: =-L112 -> -198.7094 | M29: =-M112 -> -209.5454 | N29: =-N112 -> -220.3814 | O29: =-O112 -> -231.2174 | P29: =-P112 -> -242.0534 | Q29: =Q83*-1 -> -208.51545
B30: EBIT | F30: 488.41 | G30: 933.08 | H30: 746.08 | I30: 363.18 | J30: 367.75 | K30: 388.19 | L30: =L27+L29 -> 296.17937 | M30: =M27+M29 -> 335.20691 | N30: =N27+N29 -> 378.76212 | O30: =O27+O29 -> 420.62914 | P30: =P27+P29 -> 496.28336 | Q30: =Q27+Q29 -> 670.83573
B32: Interest | F32: -111.11 | G32: -102.76 | H32: -306.74 | I32: -196.48 | J32: -279.16 | K32: -221.25 | L32: =$C$18*-1 -> -200 | M32: =$C$18*-1 -> -200 | N32: =$C$18*-1 -> -200 | O32: =$C$18*-1 -> -200 | P32: =$C$18*-1 -> -200 | Q32: =$C$18*-1 -> -200
B33: EBT | F33: 377.3 | G33: 830.32 | H33: 439.34 | I33: 166.7 | J33: 88.59 | K33: 166.94 | L33: =SUM(L30:L32) -> 96.17937 | M33: =SUM(M30:M32) -> 135.20691 | N33: =SUM(N30:N32) -> 178.76212 | O33: =SUM(O30:O32) -> 220.62914 | P33: =SUM(P30:P32) -> 296.28336 | Q33: =SUM(Q30:Q32) -> 470.83573
B35: Current Tax | F35: -109.52 | G35: -140.48 | H35: -1.25 | I35: -2.96 | J35: -6.23 | K35: -21.59 | L35: =L165 -> 42.848921 | M35: =M165 -> 59.95778 | N35: =N165 -> 70.109385 | O35: =O165 -> 80.201279 | P35: =P165 -> 98.68869 | Q35: =Q33*C19 -> 113.00058
B36: Deferred Tax | F36: 4.92 | G36: 6.92 | H36: 92.61 | I36: -25.3 | J36: 1.43 | K36: -25.57 | L36: =L166 -> -19.765872 | M36: =M166 -> -27.50812 | N36: =N166 -> -27.206476 | O36: =O166 -> -27.250284 | P36: =P166 -> -27.580685 | Q36: =Q166 -> 0
B37: Total Tax | F37: 104.6 | G37: 133.56 | H37: 91.36 | I37: 28.26 | J37: 4.8 | K37: 47.16 | L37: =L167 -> 23.083049 | M37: =M167 -> 32.449659 | N37: =N167 -> 42.902909 | O37: =O167 -> 52.950994 | P37: =P167 -> 71.108005 | Q37: =SUM(Q35:Q36) -> 113.00058
B39: Net Income | F39: 271.81 | G39: 688.55 | H39: 528.64 | I39: 127.56 | J39: 72.41 | K39: 124.79 | L39: =L33-L37 -> 73.096321 | M39: =M33-M37 -> 102.75725 | N39: =N33-N37 -> 135.85921 | O39: =O33-O37 -> 167.67815 | P39: =P33-P37 -> 225.17535 | Q39: =Q33-Q37 -> 357.83516
B41: Working Capital Schedules
F43: 2020 | G43: =F43+1 -> 2021 | H43: =G43+1 -> 2022 | I43: =H43+1 -> 2023 | J43: =I43+1 -> 2024 | K43: =J43+1 -> 2025 | L43: =K43+1 -> 2026 | M43: =L43+1 -> 2027 | N43: =M43+1 -> 2028 | ... P43: =O43+1 -> 2030 | Q43: Terms
B45: Days in Period | F45: 365 | G45: 365 | H45: 365 | I45: 365 | J45: 365 | K45: 365 | L45: 365 | M45: 365 | N45: 365 | O45: 365 | P45: 365 | Q45: 365
B46: Revenue | F46: =F7 -> 2850 | G46: =G7 -> 3760 | H46: =H7 -> 3590 | I46: =I7 -> 3030 | J46: =J7 -> 3180 | K46: =K7 -> 3440 | L46: =L7 -> 3612 | M46: =M7 -> 3756.48 | ... Q46: =Q7 -> 4436.4989
B47: COGS | F47: =F10 -> 1520 | G47: =G10 -> 1900 | H47: =H10 -> 1780 | I47: =I10 -> 1640 | J47: =J10 -> 1770 | K47: =K10 -> 1920 | L47: =L10 -> 2004.66 | M47: =M10 -> 2077.3334 | ... Q47: =Q10 -> 2318.0707
B48: SG&A | F48: =F25*-1 -> 839.52 | G48: =G25*-1 -> 922 | H48: =H25*-1 -> 1070 | I48: =I25*-1 -> 1030 | J48: =J25*-1 -> 1050 | K48: =K25*-1 -> 1130 | L48: =L25*-1 -> 1160.51 | M48: =M25*-1 -> 1189.5227 | ... Q48: =Q25*-1 -> 1281.266
B49: prepaids % SG&A | F49: =F63/F25*-1 -> 0 | G49: =G63/G25*-1 -> 0 | H49: =H63/H25*(-1) -> 0.022757009 | I49: =I63/I25*(-1) -> 0.040864078 | J49: =J63/J25*(-1) -> 0.028180952 | K49: =K63/K25*(-1) -> 0.026867257 | L49: ='DCF Inputs'!G32 -> 0.025 | M49: ='DCF Inputs'!H32 -> 0.025 | N49: ='DCF Inputs'!I32 -> 0.025 | O49: ='DCF Inputs'!J32 -> 0.025 | P49: ='DCF Inputs'!K32 -> 0.025 | Q49: ='DCF Inputs'!L32 -> 0.025
B50: other operating Assets & Revenue | F50: =F64/F46 -> 0.017378947 | G50: =G64/G46 -> 0.013779255 | H50: =H64/H46 -> 0.0086991643 | I50: =I64/I46 -> 0.011267327 | J50: =J64/J46 -> 0.014688679 | K50: =K64/K46 -> 0.013697674 | L50: ='DCF Inputs'!G33 -> 0.012 | M50: ='DCF Inputs'!H33 -> 0.012 | N50: ='DCF Inputs'!I33 -> 0.012 | O50: ='DCF Inputs'!J33 -> 0.012 | P50: ='DCF Inputs'!K33 -> 0.012 | Q50: ='DCF Inputs'!L33 -> 0.012
B51: Accrued Payroll % SG&A | F51: =F66/F46 -> 0.029775439 | G51: =G66/G46 -> 0.025760638 | H51: =H66/H46 -> 0.021350975 | I51: =I66/I46 -> 0.014468647 | J51: =J66/J46 -> 0.015940252 | K51: =K66/K46 -> 0.015968023 | L51: ='DCF Inputs'!G34 -> 0.02 | M51: ='DCF Inputs'!H34 -> 0.02 | N51: ='DCF Inputs'!I34 -> 0.02 | O51: ='DCF Inputs'!J34 -> 0.02 | P51: ='DCF Inputs'!K34 -> 0.02 | Q51: ='DCF Inputs'!L34 -> 0.02
B52: Deferred Revenue (Current) % Revenue | F52: =F67/F46 -> 0.098470175 | G52: =G67/G46 -> 0.10317287 | H52: =H67/H46 -> 0.090738162 | I52: =I67/I46 -> 0.093336634 | J52: =J67/J46 -> 0.091764151 | K52: =K67/K46 -> 0.10367442 | L52: ='DCF Inputs'!G35 -> 0.1 | M52: ='DCF Inputs'!H35 -> 0.1 | N52: ='DCF Inputs'!I35 -> 0.1 | O52: ='DCF Inputs'!J35 -> 0.1 | P52: ='DCF Inputs'!K35 -> 0.1 | Q52: ='DCF Inputs'!L35 -> 0.1
B53: Other Current Liabilities & Revenue | F53: =F68/F46 -> 0.060610526 | G53: =G68/G46 -> 0.045109043 | H53: =H68/H46 -> 0.053548747 | I53: =I68/I46 -> 0.059745875 | J53: =J68/J46 -> 0.05190566 | K53: =K68/K46 -> 0.047052326 | L53: ='DCF Inputs'!G36 -> 0.05 | M53: ='DCF Inputs'!H36 -> 0.05 | N53: ='DCF Inputs'!I36 -> 0.05 | O53: ='DCF Inputs'!J36 -> 0.05 | P53: ='DCF Inputs'!K36 -> 0.05 | Q53: ='DCF Inputs'!L36 -> 0.05
B55: AMOUNTS PER DAY
B56: Accounts Receivable | D56: (Days) | F56: =F61/F46*F45 -> 9.3542456 | G56: =G61/G46*G45 -> 7.9280718 | H56: =H61/H46*H45 -> 9.7350279 | I56: =I61/I46*I45 -> 11.275248 | J56: =J61/J46*J45 -> 13.133113 | K56: =K61/K46*K45 -> 12.832297 | L56: ='DCF Inputs'!G29 -> 10 | M56: ='DCF Inputs'!H29 -> 10 | N56: ='DCF Inputs'!I29 -> 10 | O56: ='DCF Inputs'!J29 -> 10 | P56: ='DCF Inputs'!K29 -> 10 | Q56: ='DCF Inputs'!L29 -> 10
B57: Inventory | D57: (Days) | F57: =F62/F47*F45 -> 133.69326 | G57: =G62/G47*G45 -> 144.82816 | H57: =H62/H47*H45 -> 168.76944 | I57: =I62/I47*I45 -> 173.71552 | J57: =J62/J47*J45 -> 214.46328 | K57: =K62/K47*K45 -> 160.5962 | L57: ='DCF Inputs'!G30 -> 150 | M57: ='DCF Inputs'!H30 -> 150 | N57: ='DCF Inputs'!I30 -> 150 | O57: ='DCF Inputs'!J30 -> 150 | P57: ='DCF Inputs'!K30 -> 150 | Q57: ='DCF Inputs'!L30 -> 150
B58: Accounts Payable | D58: (Days) | F58: =F65/F47*F45 -> 54.007993 | G58: =G65/G47*G45 -> 46.495237 | H58: =H65/H47*H45 -> 34.05573 | I58: =I65/I47*I45 -> 42.807378 | J58: =J65/J47*J45 -> 50.576215 | K58: =K65/K47*K45 -> 37.591198 | L58: ='DCF Inputs'!G31 -> 45 | M58: ='DCF Inputs'!H31 -> 45 | N58: ='DCF Inputs'!I31 -> 45 | O58: ='DCF Inputs'!J31 -> 45 | P58: ='DCF Inputs'!K31 -> 45 | Q58: ='DCF Inputs'!L31 -> 45
...

Sheet Comps
B2: Comparable Trading Analysis
B4: All figures in USD mm unless stated
D6: Share | E6: Enterprise | G6: EV /
B7: Peer Companies | C7: Ticker | D7: Price | E7: Value | F7: EBITDA | G7: EBITDA | H7: EBITDA Growth | J7: EPS | K7: P / E
D9: (USD/sh) | F9: (LTM) | G9: (LTM) | H9: (FY+1) | I9: (FY+2) | J9: (LTM) | K9: (LTM)
B10: Arhaus | C10: ARHS | D10: 14.63 | E10: 160.59 | F10: 15.91 | G10: =E10/F10 -> 10.093652 | H10: 0.07 | I10: 0.05 | J10: 0.62 | K10: =D10/J10 -> 23.596774
B11: Ethan Allen Interiors | C11: ETD | D11: 23.7 | E11: 488.82 | F11: 46.44 | G11: =E11/F11 -> 10.52584 | H11: 0.06 | I11: 0.06 | J11: 1.31 | K11: =D11/J11 -> 18.091603
B12: Haverty Furniture | C12: HVT | D12: 20.57 | E12: 537.43 | F12: 59.81 | G12: =E12/F12 -> 8.9856211 | H12: 0.03 | I12: 0.04 | J12: 1.58 | K12: =D12/J12 -> 13.018987
B13: MillerKnoll | C13: MLKN | D13: 16.36 | E13: 2790 | F13: 362.3 | G13: =E13/F13 -> 7.7008004 | H13: 0.05 | I13: 0.062 | J13: 0.15 | K13: =D13/J13 -> 109.06667
B14: Hooker Furnishings | C14: HOFT | D14: 203.18 | E14: 24770 | F14: 1650 | G14: =E14/F14 -> 15.012121 | H14: 0.05 | I14: 0.02 | J14: 9.06 | K14: =D14/J14 -> 22.426049
B15: Leggett & Platt | C15: LEG | D15: 6.65 | E15: 1360 | F15: 178.08 | G15: =E15/F15 -> 7.6370171 | H15: 0.1 | I15: 0.08 | J15: 0.46 | K15: =D15/J15 -> 14.456522
B16: La-Z-Boy | C16: LZB | D16: 37.57 | E16: 1810 | F16: 263.08 | G16: =E16/F16 -> 6.8800365 | H16: 0.09 | I16: 0.098 | J16: 2.03 | K16: =D16/J16 -> 18.507389
B18: Target Company Valuation
B20: All figures in USD mm unless stated
E22: Enterprise | G22: EV / | J22: Equity
B23: Target Company Valuation 1, 2 | E23: Value | F23: EBITDA | G23: EBITDA | H23: EBITDA Growth | J23: Value
F25: (LTM) | G25: (LTM) | H25: (FY+1) | I25: (FY+2)
B26: Average | E26: =G26*F26 -> 5365.0866 | F26: 538 | G26: =AVERAGE($G$11:$G$15) -> 9.9722799 | H26: 0.07 | I26: 0.07 | J26: =(E26-'DCF Inputs'!$M$41)/'DCF Inputs'!$G$50 -> 79.727033
B27: Median | E27: =G27*F27 -> 4834.2642 | F27: =F26 -> 538 | G27: =MEDIAN($G$11:$G$15) -> 8.9856211 | H27: =H26 -> 0.07 | I27: =I26 -> 0.07 | J27: =(E27-'DCF Inputs'!$M$41)/'DCF Inputs'!$G$50 -> 50.236898
B28: Maximum | E28: =G28*F28 -> 8076.5212 | F28: =F27 -> 538 | G28: =MAX($G$11:$G$15) -> 15.012121 | H28: =H27 -> 0.07 | I28: =I27 -> 0.07 | J28: =(E28-'DCF Inputs'!$M$41)/'DCF Inputs'!$G$50 -> 230.36229
B29: Minimum | E29: =G29*F29 -> 4108.7152 | F29: =F28 -> 538 | G29: =MIN($G$11:$G$15) -> 7.6370171 | H29: =H28 -> 0.07 | I29: =I28 -> 0.07 | J29: =(E29-'DCF Inputs'!$M$41)/'DCF Inputs'!$G$50 -> 9.9286213
B31: =IF(SUM(E31:G31)=2,"COMPLETE","")
I33: Target company valuation based on LTM EV/EBITDA multiple.
I34: Summary results above exclude La-Z-Boy

Sheet Transactions
B2: Precedent Transaction Analysis
B4: All figures in USD mm unless stated
E6: Offer | F6: Premium | G6: Offer | H6: Transaction | J6: EV /
B7: Announcement Date | C7: Acquirer | D7: Target | E7: Price | F7: Paid | G7: Type | H7: Value | I7: EBITDA | J7: EBITDA | K7: EBITDA Growth | M7: EPS | N7: P / E
B9: (YYYY-MM-DD) | E9: (USD/sh) | I9: (LTM) | J9: (LTM) | K9: (FY+1) | L9: (FY+2) | M9: (LTM) | N9: (LTM)
B11: 2021-05-06 1 | C11: Hellman & Friedman | D11: At Home Group Inc. | E11: 36 | F11: 0.174 | G11: Cash | H11: 2800 | I11: 310.72 | J11: =H11/I11 -> 9.0113285 | K11: 0.09 | L11: 0.08 | M11: 4.56 | N11: =E11/M11 -> 7.8947368
B12: 2021-03-03 2 | C12: Apollo Global Management | D12: The Michaels Companies, Inc. | E12: 22 | F12: 0.467 | G12: Cash | H12: 5000 | I12: 693 | J12: =H12/I12 -> 7.2150072 | K12: 0.1 | L12: 0.09 | M12: 1.94 | N12: =E12/M12 -> 11.340206
B13: 2016-08-08 3 | C13: Steinhoff International Holdings N.V. | D13: Mattress Firm Holding Corp. | E13: 64 | F13: 1.152 | G13: Cash | H13: 3800 | I13: 222.6 | J13: =H13/I13 -> 17.070979 | K13: 0.12 | L13: 0.11 | M13: 4.52 | N13: =E13/M13 -> 14.159292
B14: 2023-03-08 6 | C14: HNI Corporation | D14: Kimball International, Inc. | E14: 12.9 | F14: 0.923 | G14: Mixed | H14: 485 | I14: 51.83 | J14: =H14/I14 -> 9.357515 | K14: 0.07 | L14: 0.07 | M14: 1.2 | N14: =E14/M14 -> 10.75
B15: 2016-02-03 8 | C15: Lowe’s Companies, Inc. | D15: RONA inc. | E15: 24 | F15: 1.039 | G15: Cash | H15: 3200 | I15: 428 | J15: =H15/I15 -> 7.4766355 | K15: 0.07 | L15: 0.07 | M15: 1.2 | N15: =E15/M15 -> 20
B18: Target Company Valuation
B20: All figures in USD mm unless stated
H22: Enterprise | J22: EV / | M22: Equity
B23: Target Company Valuation 1 | H23: Value | I23: EBITDA | J23: EBITDA | K23: EBITDA Growth | M23: Value
I25: (LTM) | J25: (LTM) | K25: (FY+1) | L25: (FY+2)
B26: Average | H26: =J26*I26 -> 5394.1457 | I26: 538 | J26: =AVERAGE($J$11:$J$15) -> 10.026293 | K26: 0.07 | L26: 0.07 | M26: =(H26-'DCF Inputs'!$M$41)/'DCF Inputs'!$G$50 -> 81.341427
B27: Median | H27: =J27*I27 -> 4848.0947 | I27: =I26 -> 538 | J27: =MEDIAN($J$11:$J$15) -> 9.0113285 | K27: =K26 -> 0.07 | L27: =L26 -> 0.07 | M27: =(H27-'DCF Inputs'!$M$41)/'DCF Inputs'!$G$50 -> 51.005264
B28: Maximum | H28: =J28*I28 -> 9184.1869 | I28: =I27 -> 538 | J28: =MAX($J$11:$J$15) -> 17.070979 | K28: =K27 -> 0.07 | L28: =L27 -> 0.07 | M28: =(H28-'DCF Inputs'!$M$41)/'DCF Inputs'!$G$50 -> 291.89927
B29: Minimum | H29: =J29*I29 -> 3881.6739 | I29: =I28 -> 538 | J29: =MIN($J$11:$J$15) -> 7.2150072 | K29: =K28 -> 0.07 | L29: =L28 -> 0.07 | M29: =(H29-'DCF Inputs'!$M$41)/'DCF Inputs'!$G$50 -> -2.6847844
B31: =IF(SUM(H31:J31)=2,"COMPLETE","")
L33: Target company valuation based on LTM EV/EBITDA multiple.

Sheet RH Financial Report
B2: Income Statements
B3: USD MM | C3: 2020 | D3: 2021 | E3: 2022 | F3: 2023 | G3: 2024 | H3: 2025
B4: Revenue | C4: 2850 | D4: 3760 | E4: 3590 | F4: 3030 | G4: 3180 | H4: 3440
B5: COGS with DA | C5: -1520 | D5: -1900 | E5: -1780 | F5: -1640 | G5: -1770 | H5: -1920
B6: COGS less DA | C6: =C5+C16 -> -1355.83 | D6: =D5+D16 -> -1731.5 | E6: =E5+E16 -> -1596.23 | F6: =F5+F16 -> -1521.01 | G6: =G5+G16 -> -1639.81 | H6: =H5+H16 -> -1771.5
B7: Gross Profit | C7: 1330 | D7: 1860 | E7: 1810 | F7: 1390 | G7: 1410 | H7: 1520
B8: Operating Expenses/SG&A | C8: -840 | D8: -922 | E8: -1070 | F8: -1030 | G8: -1050 | H8: -1130
B9: EBIT / Operating Income | C9: 488.41 | D9: 933.08 | E9: 746.08 | F9: 363.18 | G9: 367.75 | H9: 388.19
B10: EBITDA | C10: 652.59 | D10: 1101 | E10: 929.85 | F10: 482.17 | G10: 497.95 | H10: 536.69
B11: Pretax Income | C11: 377.3 | D11: 830.32 | E11: 439.34 | F11: 166.7 | G11: 88.59 | H11: 166.94
B12: Income Tax (Current) | C12: -109.52 | D12: -140.48 | E12: -1.25 | F12: -2.96 | G12: -6.23 | H12: -21.59
B13: Income Tax, Deferred | C13: 4.92 | D13: 6.92 | E13: 92.61 | F13: -25.3 | G13: 1.43 | H13: -25.57
B14: Taxes | C14: -104.6 | D14: -133.56 | E14: 91.36 | F14: -28.26 | G14: -4.8 | H14: -47.16
B15: Net Income | C15: 271.81 | D15: 688.55 | E15: 528.64 | F15: 127.56 | G15: 72.41 | H15: 124.79
B16: D&A | C16: 164.17 | D16: 168.5 | E16: 183.77 | F16: 118.99 | G16: 130.19 | H16: 148.5
B17: Balance Sheet
B18: USD MM | C18: 2020 | D18: 2021 | E18: 2022 | F18: 2023 | G18: 2024 | H18: 2025
B19: Current Assets
B20: Cash & Short-term Investments | C20: 103.1 | D20: 2180 | E20: 1510 | F20: 123.69 | G20: 30.41 | H20: 41.19
B21: Accounts Receivable | C21: 73.04 | D21: 81.67 | E21: 95.75 | F21: 93.6 | G21: 114.42 | H21: 120.94
B22: Inventory | C22: 556.75 | D22: 753.9 | E22: 823.04 | F22: 780.53 | G22: 1040 | H22: 844.78
B23: Other Current Assets | C23: 49.53 | D23: 51.81 | E23: 31.23 | F23: 34.14 | G23: 46.71 | H23: 47.12
B24: Prepaid Expense | C24: 0 | D24: 0 | E24: 24.35 | F24: 42.09 | G24: 29.59 | H24: 30.36
B25: Total Current Assets | C25: 782.42 | D25: 3070 | E25: 2490 | F25: 1070 | G25: 1260 | H25: 1080
B26: Long Term Assets
B27: Net PP&E | C27: 1670 | D27: 1980 | E27: 2210 | F27: 2430 | G27: 2640 | H27: 3110
B28: Long-term Investments | C28: 104.58 | D28: 100.81 | E28: 101.47 | F28: 128.67 | G28: 126.91 | H28: 119.75
B29: Intangible Assets | C29: 212.76 | D29: 214.26 | E29: 215.68 | F29: 216.96 | G29: 217.06 | H29: 224.02
B30: Total Assets | C30: 2900 | D30: 5540 | E30: 5310 | F30: 4140 | G30: 4550 | H30: 4840
B31: Current Liability
B32: Short-term Debt | C32: 108.94 | D32: 135.96 | E32: 125.25 | F32: 167.03 | G32: 147.08 | H32: 156.53
B33: Accounts Payable | C33: 224.91 | D33: 242.03 | E33: 166.08 | F33: 192.34 | G33: 245.26 | H33: 197.74
B34: Accrued Payroll | C34: 84.86 | D34: 96.86 | E34: 76.65 | F34: 43.84 | G34: 50.69 | H34: 54.93
B35: Deferred Revenue (Current) | C35: 280.64 | D35: 387.93 | E35: 325.75 | F35: 282.81 | G35: 291.81 | H35: 356.64
B36: Other Current Liabilities | C36: 172.74 | D36: 169.61 | E36: 192.24 | F36: 181.03 | G36: 165.06 | H36: 161.86
B37: Total Current Liabilities | C37: 921.63 | D37: 1060 | E37: 885.97 | F37: 872.87 | G37: 905.13 | H37: 930.61
B38: Long Term Liability
B39: Long-term Debt | C39: 1510 | D39: 3300 | E39: 3620 | F39: 3550 | G39: 3790 | H39: 3810
B40: Total Debt | C40: 1620 | D40: 3430 | E40: 3750 | F40: 3720 | G40: 3940 | H40: 3970
B41: Net Debt | C41: 1520 | D41: 1250 | E41: 2240 | F41: 3590 | G41: 3910 | H41: 3930
...
